<?xml version="1.0" ?>
<robot name="cambot" xmlns:xacro="http://www.ros.org/wiki/xacro">

<xacro:include filename="$(find cambot_description)/urdf/materials.xacro" />
<xacro:include filename="$(find cambot_description)/urdf/cambot.trans" />
<xacro:include filename="$(find cambot_description)/urdf/cambot.gazebo" />

<link name="base_footprint">
</link>
<joint name="base_footprint_joint" type="fixed">
<parent link="base_footprint"/>
<child link="base_link"/>
<origin xyz="0 0 0" rpy="0 0 0"/>
</joint>


<link name="base_link">
  <inertial>
    <origin xyz="0.031870478387917095 -0.020005619593945374 0.06941706839813641" rpy="0 0 0"/>
    <mass value="2.172586468134362"/>
    <inertia ixx="0.009891" iyy="0.013269" izz="0.014819" ixy="-2e-06" iyz="-1e-06" ixz="-0.000562"/>
  </inertial>
  <visual>
    <origin xyz="0 0 0" rpy="0 0 0"/>
    <geometry>
      <mesh filename="file://$(find cambot_description)/meshes/base_link.stl" scale="0.001 0.001 0.001"/>
    </geometry>
    <material name="orange"/>
  </visual>
  <collision>
    <origin xyz="0 0 0" rpy="0 0 0"/>
    <geometry>
      <mesh filename="file://$(find cambot_description)/meshes/base_link.stl" scale="0.001 0.001 0.001"/>
    </geometry>
  </collision>
</link>

<link name="shoulder_1">
  <inertial>
    <origin xyz="-2.430504438544201e-07 -0.004991671159117982 0.056237622393101955" rpy="0 0 0"/>
    <mass value="0.18433349119517356"/>
    <inertia ixx="0.000405" iyy="0.00039" izz="5.3e-05" ixy="0.0" iyz="5.2e-05" ixz="-0.0"/>
  </inertial>
  <visual>
    <origin xyz="-0.045826 0.02 -0.18" rpy="0 0 0"/>
    <geometry>
      <mesh filename="file://$(find cambot_description)/meshes/shoulder_1.stl" scale="0.001 0.001 0.001"/>
    </geometry>
    <material name="black"/>
  </visual>
  <collision>
    <origin xyz="-0.045826 0.02 -0.18" rpy="0 0 0"/>
    <geometry>
      <mesh filename="file://$(find cambot_description)/meshes/shoulder_1.stl" scale="0.001 0.001 0.001"/>
    </geometry>
  </collision>
</link>

<link name="elbow_1">
  <inertial>
    <origin xyz="-2.43050441571524e-07 -0.04031131608347646 0.03975245049583381" rpy="0 0 0"/>
    <mass value="0.19120204614626873"/>
    <inertia ixx="0.000366" iyy="0.000305" izz="9.9e-05" ixy="-0.0" iyz="6.4e-05" ixz="0.0"/>
  </inertial>
  <visual>
    <origin xyz="-0.045826 0.07 -0.295" rpy="0 0 0"/>
    <geometry>
      <mesh filename="file://$(find cambot_description)/meshes/elbow_1.stl" scale="0.001 0.001 0.001"/>
    </geometry>
    <material name="orange"/>
  </visual>
  <collision>
    <origin xyz="-0.045826 0.07 -0.295" rpy="0 0 0"/>
    <geometry>
      <mesh filename="file://$(find cambot_description)/meshes/elbow_1.stl" scale="0.001 0.001 0.001"/>
    </geometry>
  </collision>
</link>

<link name="proximal_wrist_1">
  <inertial>
    <origin xyz="-2.4305043990618946e-07 0.05036122601814666 0.03491062753470031" rpy="0 0 0"/>
    <mass value="0.219444964102041"/>
    <inertia ixx="0.000439" iyy="0.000309" izz="0.000173" ixy="-0.0" iyz="-7.1e-05" ixz="0.0"/>
  </inertial>
  <visual>
    <origin xyz="-0.045826 0.085 -0.395" rpy="0 0 0"/>
    <geometry>
      <mesh filename="file://$(find cambot_description)/meshes/proximal_wrist_1.stl" scale="0.001 0.001 0.001"/>
    </geometry>
    <material name="black"/>
  </visual>
  <collision>
    <origin xyz="-0.045826 0.085 -0.395" rpy="0 0 0"/>
    <geometry>
      <mesh filename="file://$(find cambot_description)/meshes/proximal_wrist_1.stl" scale="0.001 0.001 0.001"/>
    </geometry>
  </collision>
</link>

<link name="intermediate_wrist_1">
  <inertial>
    <origin xyz="-2.4305044015598964e-07 -0.04031131608347617 0.039752450495832425" rpy="0 0 0"/>
    <mass value="0.1912020461462686"/>
    <inertia ixx="0.000366" iyy="0.000305" izz="9.9e-05" ixy="-0.0" iyz="6.4e-05" ixz="0.0"/>
  </inertial>
  <visual>
    <origin xyz="-0.045826 0.07 -0.48" rpy="0 0 0"/>
    <geometry>
      <mesh filename="file://$(find cambot_description)/meshes/intermediate_wrist_1.stl" scale="0.001 0.001 0.001"/>
    </geometry>
    <material name="orange"/>
  </visual>
  <collision>
    <origin xyz="-0.045826 0.07 -0.48" rpy="0 0 0"/>
    <geometry>
      <mesh filename="file://$(find cambot_description)/meshes/intermediate_wrist_1.stl" scale="0.001 0.001 0.001"/>
    </geometry>
  </collision>
</link>

<link name="distal_wrist_1">
  <inertial>
    <origin xyz="-2.4305043990618946e-07 0.05036122601814667 0.0349106275346982" rpy="0 0 0"/>
    <mass value="0.2194449641020409"/>
    <inertia ixx="0.000439" iyy="0.000309" izz="0.000173" ixy="0.0" iyz="-7.1e-05" ixz="-0.0"/>
  </inertial>
  <visual>
    <origin xyz="-0.045826 0.085 -0.58" rpy="0 0 0"/>
    <geometry>
      <mesh filename="file://$(find cambot_description)/meshes/distal_wrist_1.stl" scale="0.001 0.001 0.001"/>
    </geometry>
    <material name="black"/>
  </visual>
  <collision>
    <origin xyz="-0.045826 0.085 -0.58" rpy="0 0 0"/>
    <geometry>
      <mesh filename="file://$(find cambot_description)/meshes/distal_wrist_1.stl" scale="0.001 0.001 0.001"/>
    </geometry>
  </collision>
</link>

<link name="distal_section_1">
  <inertial>
    <origin xyz="-2.4305043969108375e-07 -0.03807586093568524 0.019860450301824484" rpy="0 0 0"/>
    <mass value="0.13796540000679278"/>
    <inertia ixx="0.000151" iyy="9.5e-05" izz="8.3e-05" ixy="-0.0" iyz="4.6e-05" ixz="-0.0"/>
  </inertial>
  <visual>
    <origin xyz="-0.045826 0.07 -0.665" rpy="0 0 0"/>
    <geometry>
      <mesh filename="file://$(find cambot_description)/meshes/distal_section_1.stl" scale="0.001 0.001 0.001"/>
    </geometry>
    <material name="orange"/>
  </visual>
  <collision>
    <origin xyz="-0.045826 0.07 -0.665" rpy="0 0 0"/>
    <geometry>
      <mesh filename="file://$(find cambot_description)/meshes/distal_section_1.stl" scale="0.001 0.001 0.001"/>
    </geometry>
  </collision>
</link>

<link name="tool_flange_1">
  <inertial>
    <origin xyz="-2.428039157509332e-07 1.232609153634101e-10 0.0062875748255590835" rpy="0 0 0"/>
    <mass value="0.036328076720912754"/>
    <inertia ixx="7e-06" iyy="7e-06" izz="7e-06" ixy="-0.0" iyz="-0.0" ixz="-0.0"/>
  </inertial>
  <visual>
    <origin xyz="-0.045826 0.125 -0.745" rpy="0 0 0"/>
    <geometry>
      <mesh filename="file://$(find cambot_description)/meshes/tool_flange_1.stl" scale="0.001 0.001 0.001"/>
    </geometry>
    <material name="green"/>
  </visual>
  <collision>
    <origin xyz="-0.045826 0.125 -0.745" rpy="0 0 0"/>
    <geometry>
      <mesh filename="file://$(find cambot_description)/meshes/tool_flange_1.stl" scale="0.001 0.001 0.001"/>
    </geometry>
  </collision>
</link>

<link name="camera_1">
  <inertial>
    <origin xyz="-2.3962317705766845e-07 3.597005395289399e-05 0.001054296634018459" rpy="0 0 0"/>
    <mass value="0.0001812213173875097"/>
    <inertia ixx="0.0" iyy="0.0" izz="0.0" ixy="-0.0" iyz="-0.0" ixz="-0.0"/>
  </inertial>
  <visual>
    <origin xyz="-0.045826 0.125 -0.77" rpy="0 0 0"/>
    <geometry>
      <mesh filename="file://$(find cambot_description)/meshes/camera_1.stl" scale="0.001 0.001 0.001"/>
    </geometry>
    <material name="black"/>
  </visual>
  <collision>
    <origin xyz="-0.045826 0.125 -0.77" rpy="0 0 0"/>
    <geometry>
      <mesh filename="file://$(find cambot_description)/meshes/camera_1.stl" scale="0.001 0.001 0.001"/>
    </geometry>
  </collision>
</link>

<joint name="camera_optical_joint" type="fixed">
<origin xyz="0 0 0" rpy="${-pi/2} 0 ${-pi/2}" />
<parent link="camera_1" />
<child link="camera_link_optical" />
</joint>
<link name="camera_link_optical"></link>


<link name="left_strcamera_1">
  <inertial>
    <origin xyz="-0.5340002394741429 -0.005999998286366576 0.43022693608457757" rpy="0 0 0"/>
    <mass value="0.0002297800954592406"/>
    <inertia ixx="0.0" iyy="0.0" izz="0.0" ixy="-0.0" iyz="-0.0" ixz="0.0"/>
  </inertial>
  <visual>
    <origin xyz="-0.585826 0.115 -0.340826" rpy="0 0 0"/>
    <geometry>
      <mesh filename="file://$(find cambot_description)/meshes/left_strcamera_1.stl" scale="0.001 0.001 0.001"/>
    </geometry>
    <material name="red"/>
  </visual>
  <collision>
    <origin xyz="-0.585826 0.115 -0.340826" rpy="0 0 0"/>
    <geometry>
      <mesh filename="file://$(find cambot_description)/meshes/left_strcamera_1.stl" scale="0.001 0.001 0.001"/>
    </geometry>
  </collision>
</link>

<link name="right_strcamera_1">
  <inertial>
    <origin xyz="-0.5340002394741429 -0.013999998286366513 0.43022693608457757" rpy="0 0 0"/>
    <mass value="0.0002297800954592406"/>
    <inertia ixx="0.0" iyy="0.0" izz="0.0" ixy="0.0" iyz="-0.0" ixz="-0.0"/>
  </inertial>
  <visual>
    <origin xyz="-0.585826 0.115 -0.340826" rpy="0 0 0"/>
    <geometry>
      <mesh filename="file://$(find cambot_description)/meshes/right_strcamera_1.stl" scale="0.001 0.001 0.001"/>
    </geometry>
    <material name="red"/>
  </visual>
  <collision>
    <origin xyz="-0.585826 0.115 -0.340826" rpy="0 0 0"/>
    <geometry>
      <mesh filename="file://$(find cambot_description)/meshes/right_strcamera_1.stl" scale="0.001 0.001 0.001"/>
    </geometry>
  </collision>
</link>

<joint name="base_joint" type="continuous">
  <origin xyz="0.045826 -0.02 0.18" rpy="0 0 0"/>
  <parent link="base_link"/>
  <child link="shoulder_1"/>
  <axis xyz="0.0 0.0 1.0"/>
</joint>

<joint name="shoulder_joint" type="revolute">
  <origin xyz="0.0 -0.05 0.115" rpy="0 0 0"/>
  <parent link="shoulder_1"/>
  <child link="elbow_1"/>
  <axis xyz="-0.0 -1.0 0.0"/>
  <limit upper="1.570796" lower="-1.570796" effort="100" velocity="100"/>
</joint>

<joint name="elbow_joint" type="revolute">
  <origin xyz="0.0 -0.015 0.1" rpy="0 0 0"/>
  <parent link="elbow_1"/>
  <child link="proximal_wrist_1"/>
  <axis xyz="0.0 1.0 -0.0"/>
  <limit upper="0.872665" lower="-0.872665" effort="100" velocity="100"/>
</joint>

<joint name="proximal_wrist_joint" type="revolute">
  <origin xyz="0.0 0.015 0.085" rpy="0 0 0"/>
  <parent link="proximal_wrist_1"/>
  <child link="intermediate_wrist_1"/>
  <axis xyz="-0.0 -1.0 -0.0"/>
  <limit upper="1.047198" lower="-1.047198" effort="100" velocity="100"/>
</joint>

<joint name="inter_wrist_joint" type="revolute">
  <origin xyz="0.0 -0.015 0.1" rpy="0 0 0"/>
  <parent link="intermediate_wrist_1"/>
  <child link="distal_wrist_1"/>
  <axis xyz="0.0 1.0 0.0"/>
  <limit upper="1.570796" lower="-1.570796" effort="100" velocity="100"/>
</joint>

<joint name="distal_wrist_joint" type="revolute">
  <origin xyz="0.0 0.015 0.085" rpy="0 0 0"/>
  <parent link="distal_wrist_1"/>
  <child link="distal_section_1"/>
  <axis xyz="-0.0 -1.0 -0.0"/>
  <limit upper="1.570796" lower="-1.570796" effort="100" velocity="100"/>
</joint>

<joint name="tool_joint" type="continuous">
  <origin xyz="0.0 -0.055 0.08" rpy="0 0 0"/>
  <parent link="distal_section_1"/>
  <child link="tool_flange_1"/>
  <axis xyz="0.0 -0.0 1.0"/>
</joint>

<joint name="camera_joint" type="fixed">
  <origin xyz="0.0 0.0 0.025" rpy="0 0 0"/>
  <parent link="tool_flange_1"/>
  <child link="camera_1"/>
</joint>

<joint name="leftstrcamera_joint" type="fixed">
  <origin xyz="0.54 0.01 -0.404174" rpy="0 0 0"/>
  <parent link="tool_flange_1"/>
  <child link="left_strcamera_1"/>
</joint>

<joint name="rightstrcamera_joint" type="fixed">
  <origin xyz="0.54 0.01 -0.404174" rpy="0 0 0"/>
  <parent link="tool_flange_1"/>
  <child link="right_strcamera_1"/>
</joint>

</robot>
