<?xml version="1.0" ?>
<!-- =================================================================================== -->
<!-- |    This document was autogenerated by xacro from cambot.xacro                   | -->
<!-- |    EDITING THIS FILE BY HAND IS NOT RECOMMENDED                                 | -->
<!-- =================================================================================== -->
<robot name="cambot">
  <material name="silver">
    <color rgba="0.700 0.700 0.700 1.000"/>
  </material>
  <material name="black">
    <color rgba="0.0 0.0 0.0 1.0"/>
  </material>
  <material name="blue">
    <color rgba="0.203125 0.23828125 0.28515625 1.0"/>
  </material>
  <material name="green">
    <color rgba="0.0 0.8 0.0 1.0"/>
  </material>
  <material name="grey">
    <color rgba="0.2 0.2 0.2 1.0"/>
  </material>
  <material name="orange">
    <color rgba="1.0 0.423529411765 0.0392156862745 1.0"/>
  </material>
  <material name="brown">
    <color rgba="0.870588235294 0.811764705882 0.764705882353 1.0"/>
  </material>
  <material name="red">
    <color rgba="0.80078125 0.12890625 0.1328125 1.0"/>
  </material>
  <material name="white">
    <color rgba="1.0 1.0 1.0 1.0"/>
  </material>
  <transmission name="base_joint_tran">
    <type>transmission_interface/SimpleTransmission</type>
    <joint name="base_joint">
      <hardwareInterface>hardware_interface/EffortJointInterface</hardwareInterface>
    </joint>
    <actuator name="base_joint_actr">
      <hardwareInterface>hardware_interface/EffortJointInterface</hardwareInterface>
      <mechanicalReduction>1</mechanicalReduction>
    </actuator>
  </transmission>
  <transmission name="shoulder_joint_tran">
    <type>transmission_interface/SimpleTransmission</type>
    <joint name="shoulder_joint">
      <hardwareInterface>hardware_interface/EffortJointInterface</hardwareInterface>
    </joint>
    <actuator name="shoulder_joint_actr">
      <hardwareInterface>hardware_interface/EffortJointInterface</hardwareInterface>
      <mechanicalReduction>1</mechanicalReduction>
    </actuator>
  </transmission>
  <transmission name="elbow_joint_tran">
    <type>transmission_interface/SimpleTransmission</type>
    <joint name="elbow_joint">
      <hardwareInterface>hardware_interface/EffortJointInterface</hardwareInterface>
    </joint>
    <actuator name="elbow_joint_actr">
      <hardwareInterface>hardware_interface/EffortJointInterface</hardwareInterface>
      <mechanicalReduction>1</mechanicalReduction>
    </actuator>
  </transmission>
  <transmission name="proximal_wrist_joint_tran">
    <type>transmission_interface/SimpleTransmission</type>
    <joint name="proximal_wrist_joint">
      <hardwareInterface>hardware_interface/EffortJointInterface</hardwareInterface>
    </joint>
    <actuator name="proximal_wrist_joint_actr">
      <hardwareInterface>hardware_interface/EffortJointInterface</hardwareInterface>
      <mechanicalReduction>1</mechanicalReduction>
    </actuator>
  </transmission>
  <transmission name="inter_wrist_joint_tran">
    <type>transmission_interface/SimpleTransmission</type>
    <joint name="inter_wrist_joint">
      <hardwareInterface>hardware_interface/EffortJointInterface</hardwareInterface>
    </joint>
    <actuator name="inter_wrist_joint_actr">
      <hardwareInterface>hardware_interface/EffortJointInterface</hardwareInterface>
      <mechanicalReduction>1</mechanicalReduction>
    </actuator>
  </transmission>
  <transmission name="distal_wrist_joint_tran">
    <type>transmission_interface/SimpleTransmission</type>
    <joint name="distal_wrist_joint">
      <hardwareInterface>hardware_interface/EffortJointInterface</hardwareInterface>
    </joint>
    <actuator name="distal_wrist_joint_actr">
      <hardwareInterface>hardware_interface/EffortJointInterface</hardwareInterface>
      <mechanicalReduction>1</mechanicalReduction>
    </actuator>
  </transmission>
  <transmission name="tool_joint_tran">
    <type>transmission_interface/SimpleTransmission</type>
    <joint name="tool_joint">
      <hardwareInterface>hardware_interface/EffortJointInterface</hardwareInterface>
    </joint>
    <actuator name="tool_joint_actr">
      <hardwareInterface>hardware_interface/EffortJointInterface</hardwareInterface>
      <mechanicalReduction>1</mechanicalReduction>
    </actuator>
  </transmission>
  <gazebo>
    <plugin filename="libgazebo_ros_control.so" name="control"/>
  </gazebo>
  <gazebo reference="base_link">
    <material>Gazebo/Orange</material>
    <mu1>0.2</mu1>
    <mu2>0.2</mu2>
    <self_collide>true</self_collide>
    <gravity>true</gravity>
  </gazebo>
  <gazebo reference="shoulder_1">
    <material>Gazebo/Black</material>
    <mu1>0.2</mu1>
    <mu2>0.2</mu2>
    <self_collide>true</self_collide>
  </gazebo>
  <gazebo reference="elbow_1">
    <material>Gazebo/Orange</material>
    <mu1>0.2</mu1>
    <mu2>0.2</mu2>
    <self_collide>true</self_collide>
  </gazebo>
  <gazebo reference="proximal_wrist_1">
    <material>Gazebo/Black</material>
    <mu1>0.2</mu1>
    <mu2>0.2</mu2>
    <self_collide>true</self_collide>
  </gazebo>
  <gazebo reference="intermediate_wrist_1">
    <material>Gazebo/Orange</material>
    <mu1>0.2</mu1>
    <mu2>0.2</mu2>
    <self_collide>true</self_collide>
  </gazebo>
  <gazebo reference="distal_wrist_1">
    <material>Gazebo/Black</material>
    <mu1>0.2</mu1>
    <mu2>0.2</mu2>
    <self_collide>true</self_collide>
  </gazebo>
  <gazebo reference="distal_section_1">
    <material>Gazebo/Orange</material>
    <mu1>0.2</mu1>
    <mu2>0.2</mu2>
    <self_collide>true</self_collide>
  </gazebo>
  <gazebo reference="tool_flange_1">
    <material>Gazebo/Green</material>
    <mu1>0.2</mu1>
    <mu2>0.2</mu2>
    <self_collide>true</self_collide>
  </gazebo>
  <gazebo reference="camera_1">
    <material>Gazebo/Black</material>
    <mu1>0.2</mu1>
    <mu2>0.2</mu2>
    <self_collide>true</self_collide>
  </gazebo>
  <gazebo reference="camera_1">
    <material>Gazebo/Black</material>
    <self_collide>true</self_collide>
    <mu1>0.2</mu1>
    <mu2>0.2</mu2>
    <sensor name="camera" type="depth">
      <pose> 0 0 0 0 0 0 </pose>
      <visualize>true</visualize>
      <update_rate>10</update_rate>
      <camera>
        <horizontal_fov>1.089</horizontal_fov>
        <image>
          <format>B8G8R8</format>
          <width>1280</width>
          <height>640</height>
        </image>
        <clip>
          <near>0.05</near>
          <far>8.0</far>
        </clip>
      </camera>
      <plugin filename="libgazebo_ros_camera.so" name="camera_controller">
        <frame_name>camera_link_optical</frame_name>
        <min_depth>0.1</min_depth>
        <max_depth>100.0</max_depth>
      </plugin>
    </sensor>
  </gazebo>
  <gazebo reference="left_strcamera_1">
    <material>Gazebo/Red</material>
    <mu1>0.2</mu1>
    <mu2>0.2</mu2>
    <self_collide>true</self_collide>
  </gazebo>
  <gazebo reference="right_strcamera_1">
    <material>Gazebo/Red</material>
    <mu1>0.2</mu1>
    <mu2>0.2</mu2>
    <self_collide>true</self_collide>
  </gazebo>
  <gazebo reference="left_strcamera_1">
    <sensor name="stereo_camera" type="multicamera">
      <update_rate>30.0</update_rate>
      <camera name="left">
        <horizontal_fov>1.3962634</horizontal_fov>
        <image>
          <width>800</width>
          <height>800</height>
          <format>R8G8B8</format>
        </image>
        <clip>
          <near>0.02</near>
          <far>300</far>
        </clip>
        <noise>
          <type>gaussian</type>
          <mean>0.0</mean>
          <stddev>0.007</stddev>
        </noise>
      </camera>
      <camera name="right">
        <pose>0 -0.07 0 0 0 0</pose>
        <horizontal_fov>1.3962634</horizontal_fov>
        <image>
          <width>800</width>
          <height>800</height>
          <format>R8G8B8</format>
        </image>
        <clip>
          <near>0.02</near>
          <far>300</far>
        </clip>
        <noise>
          <type>gaussian</type>
          <mean>0.0</mean>
          <stddev>0.007</stddev>
        </noise>
      </camera>
      <plugin filename="libgazebo_ros_multicamera.so" name="stereo_camera_controller">
        <alwaysOn>true</alwaysOn>
        <updateRate>0.0</updateRate>
        <cameraName>multisense_sl/camera</cameraName>
        <imageTopicName>image_raw</imageTopicName>
        <cameraInfoTopicName>camera_info</cameraInfoTopicName>
        <frameName>left_camera_optical_frame</frameName>
        <!--<rightFrameName>right_camera_optical_frame</rightFrameName>-->
        <hackBaseline>0.07</hackBaseline>
        <distortionK1>0.0</distortionK1>
        <distortionK2>0.0</distortionK2>
        <distortionK3>0.0</distortionK3>
        <distortionT1>0.0</distortionT1>
        <distortionT2>0.0</distortionT2>
      </plugin>
    </sensor>
  </gazebo>
  <link name="base_footprint">
</link>
  <joint name="base_footprint_joint" type="fixed">
    <parent link="base_footprint"/>
    <child link="base_link"/>
    <origin rpy="0 0 0" xyz="0 0 0"/>
  </joint>
  <link name="base_link">
    <inertial>
      <origin rpy="0 0 0" xyz="0.031870478387917095 -0.020005619593945374 0.06941706839813641"/>
      <mass value="2.172586468134362"/>
      <inertia ixx="0.009891" ixy="-2e-06" ixz="-0.000562" iyy="0.013269" iyz="-1e-06" izz="0.014819"/>
    </inertial>
    <visual>
      <origin rpy="0 0 0" xyz="0 0 0"/>
      <geometry>
        <mesh filename="file:///home/anandu_2004/manipulator_ws/install/cambot_description/share/cambot_description/meshes/base_link.stl" scale="0.001 0.001 0.001"/>
      </geometry>
      <material name="orange"/>
    </visual>
    <collision>
      <origin rpy="0 0 0" xyz="0 0 0"/>
      <geometry>
        <mesh filename="file:///home/anandu_2004/manipulator_ws/install/cambot_description/share/cambot_description/meshes/base_link.stl" scale="0.001 0.001 0.001"/>
      </geometry>
    </collision>
  </link>
  <link name="shoulder_1">
    <inertial>
      <origin rpy="0 0 0" xyz="-2.430504438544201e-07 -0.004991671159117982 0.056237622393101955"/>
      <mass value="0.18433349119517356"/>
      <inertia ixx="0.000405" ixy="0.0" ixz="-0.0" iyy="0.00039" iyz="5.2e-05" izz="5.3e-05"/>
    </inertial>
    <visual>
      <origin rpy="0 0 0" xyz="-0.045826 0.02 -0.18"/>
      <geometry>
        <mesh filename="file:///home/anandu_2004/manipulator_ws/install/cambot_description/share/cambot_description/meshes/shoulder_1.stl" scale="0.001 0.001 0.001"/>
      </geometry>
      <material name="black"/>
    </visual>
    <collision>
      <origin rpy="0 0 0" xyz="-0.045826 0.02 -0.18"/>
      <geometry>
        <mesh filename="file:///home/anandu_2004/manipulator_ws/install/cambot_description/share/cambot_description/meshes/shoulder_1.stl" scale="0.001 0.001 0.001"/>
      </geometry>
    </collision>
  </link>
  <link name="elbow_1">
    <inertial>
      <origin rpy="0 0 0" xyz="-2.43050441571524e-07 -0.04031131608347646 0.03975245049583381"/>
      <mass value="0.19120204614626873"/>
      <inertia ixx="0.000366" ixy="-0.0" ixz="0.0" iyy="0.000305" iyz="6.4e-05" izz="9.9e-05"/>
    </inertial>
    <visual>
      <origin rpy="0 0 0" xyz="-0.045826 0.07 -0.295"/>
      <geometry>
        <mesh filename="file:///home/anandu_2004/manipulator_ws/install/cambot_description/share/cambot_description/meshes/elbow_1.stl" scale="0.001 0.001 0.001"/>
      </geometry>
      <material name="orange"/>
    </visual>
    <collision>
      <origin rpy="0 0 0" xyz="-0.045826 0.07 -0.295"/>
      <geometry>
        <mesh filename="file:///home/anandu_2004/manipulator_ws/install/cambot_description/share/cambot_description/meshes/elbow_1.stl" scale="0.001 0.001 0.001"/>
      </geometry>
    </collision>
  </link>
  <link name="proximal_wrist_1">
    <inertial>
      <origin rpy="0 0 0" xyz="-2.4305043990618946e-07 0.05036122601814666 0.03491062753470031"/>
      <mass value="0.219444964102041"/>
      <inertia ixx="0.000439" ixy="-0.0" ixz="0.0" iyy="0.000309" iyz="-7.1e-05" izz="0.000173"/>
    </inertial>
    <visual>
      <origin rpy="0 0 0" xyz="-0.045826 0.085 -0.395"/>
      <geometry>
        <mesh filename="file:///home/anandu_2004/manipulator_ws/install/cambot_description/share/cambot_description/meshes/proximal_wrist_1.stl" scale="0.001 0.001 0.001"/>
      </geometry>
      <material name="black"/>
    </visual>
    <collision>
      <origin rpy="0 0 0" xyz="-0.045826 0.085 -0.395"/>
      <geometry>
        <mesh filename="file:///home/anandu_2004/manipulator_ws/install/cambot_description/share/cambot_description/meshes/proximal_wrist_1.stl" scale="0.001 0.001 0.001"/>
      </geometry>
    </collision>
  </link>
  <link name="intermediate_wrist_1">
    <inertial>
      <origin rpy="0 0 0" xyz="-2.4305044015598964e-07 -0.04031131608347617 0.039752450495832425"/>
      <mass value="0.1912020461462686"/>
      <inertia ixx="0.000366" ixy="-0.0" ixz="0.0" iyy="0.000305" iyz="6.4e-05" izz="9.9e-05"/>
    </inertial>
    <visual>
      <origin rpy="0 0 0" xyz="-0.045826 0.07 -0.48"/>
      <geometry>
        <mesh filename="file:///home/anandu_2004/manipulator_ws/install/cambot_description/share/cambot_description/meshes/intermediate_wrist_1.stl" scale="0.001 0.001 0.001"/>
      </geometry>
      <material name="orange"/>
    </visual>
    <collision>
      <origin rpy="0 0 0" xyz="-0.045826 0.07 -0.48"/>
      <geometry>
        <mesh filename="file:///home/anandu_2004/manipulator_ws/install/cambot_description/share/cambot_description/meshes/intermediate_wrist_1.stl" scale="0.001 0.001 0.001"/>
      </geometry>
    </collision>
  </link>
  <link name="distal_wrist_1">
    <inertial>
      <origin rpy="0 0 0" xyz="-2.4305043990618946e-07 0.05036122601814667 0.0349106275346982"/>
      <mass value="0.2194449641020409"/>
      <inertia ixx="0.000439" ixy="0.0" ixz="-0.0" iyy="0.000309" iyz="-7.1e-05" izz="0.000173"/>
    </inertial>
    <visual>
      <origin rpy="0 0 0" xyz="-0.045826 0.085 -0.58"/>
      <geometry>
        <mesh filename="file:///home/anandu_2004/manipulator_ws/install/cambot_description/share/cambot_description/meshes/distal_wrist_1.stl" scale="0.001 0.001 0.001"/>
      </geometry>
      <material name="black"/>
    </visual>
    <collision>
      <origin rpy="0 0 0" xyz="-0.045826 0.085 -0.58"/>
      <geometry>
        <mesh filename="file:///home/anandu_2004/manipulator_ws/install/cambot_description/share/cambot_description/meshes/distal_wrist_1.stl" scale="0.001 0.001 0.001"/>
      </geometry>
    </collision>
  </link>
  <link name="distal_section_1">
    <inertial>
      <origin rpy="0 0 0" xyz="-2.4305043969108375e-07 -0.03807586093568524 0.019860450301824484"/>
      <mass value="0.13796540000679278"/>
      <inertia ixx="0.000151" ixy="-0.0" ixz="-0.0" iyy="9.5e-05" iyz="4.6e-05" izz="8.3e-05"/>
    </inertial>
    <visual>
      <origin rpy="0 0 0" xyz="-0.045826 0.07 -0.665"/>
      <geometry>
        <mesh filename="file:///home/anandu_2004/manipulator_ws/install/cambot_description/share/cambot_description/meshes/distal_section_1.stl" scale="0.001 0.001 0.001"/>
      </geometry>
      <material name="orange"/>
    </visual>
    <collision>
      <origin rpy="0 0 0" xyz="-0.045826 0.07 -0.665"/>
      <geometry>
        <mesh filename="file:///home/anandu_2004/manipulator_ws/install/cambot_description/share/cambot_description/meshes/distal_section_1.stl" scale="0.001 0.001 0.001"/>
      </geometry>
    </collision>
  </link>
  <link name="tool_flange_1">
    <inertial>
      <origin rpy="0 0 0" xyz="-2.428039157509332e-07 1.232609153634101e-10 0.0062875748255590835"/>
      <mass value="0.036328076720912754"/>
      <inertia ixx="7e-06" ixy="-0.0" ixz="-0.0" iyy="7e-06" iyz="-0.0" izz="7e-06"/>
    </inertial>
    <visual>
      <origin rpy="0 0 0" xyz="-0.045826 0.125 -0.745"/>
      <geometry>
        <mesh filename="file:///home/anandu_2004/manipulator_ws/install/cambot_description/share/cambot_description/meshes/tool_flange_1.stl" scale="0.001 0.001 0.001"/>
      </geometry>
      <material name="green"/>
    </visual>
    <collision>
      <origin rpy="0 0 0" xyz="-0.045826 0.125 -0.745"/>
      <geometry>
        <mesh filename="file:///home/anandu_2004/manipulator_ws/install/cambot_description/share/cambot_description/meshes/tool_flange_1.stl" scale="0.001 0.001 0.001"/>
      </geometry>
    </collision>
  </link>
  <link name="camera_1">
    <inertial>
      <origin rpy="0 0 0" xyz="-2.3962317705766845e-07 3.597005395289399e-05 0.001054296634018459"/>
      <mass value="0.0001812213173875097"/>
      <inertia ixx="0.0" ixy="-0.0" ixz="-0.0" iyy="0.0" iyz="-0.0" izz="0.0"/>
    </inertial>
    <visual>
      <origin rpy="0 0 0" xyz="-0.045826 0.125 -0.77"/>
      <geometry>
        <mesh filename="file:///home/anandu_2004/manipulator_ws/install/cambot_description/share/cambot_description/meshes/camera_1.stl" scale="0.001 0.001 0.001"/>
      </geometry>
      <material name="black"/>
    </visual>
    <collision>
      <origin rpy="0 0 0" xyz="-0.045826 0.125 -0.77"/>
      <geometry>
        <mesh filename="file:///home/anandu_2004/manipulator_ws/install/cambot_description/share/cambot_description/meshes/camera_1.stl" scale="0.001 0.001 0.001"/>
      </geometry>
    </collision>
  </link>
  <joint name="camera_optical_joint" type="fixed">
    <origin rpy="-1.5707963267948966 0 -1.5707963267948966" xyz="0 0 0"/>
    <parent link="camera_1"/>
    <child link="camera_link_optical"/>
  </joint>
  <link name="camera_link_optical"/>
  <link name="left_strcamera_1">
    <inertial>
      <origin rpy="0 0 0" xyz="-0.5340002394741429 -0.005999998286366576 0.43022693608457757"/>
      <mass value="0.0002297800954592406"/>
      <inertia ixx="0.0" ixy="-0.0" ixz="0.0" iyy="0.0" iyz="-0.0" izz="0.0"/>
    </inertial>
    <visual>
      <origin rpy="0 0 0" xyz="-0.585826 0.115 -0.340826"/>
      <geometry>
        <mesh filename="file:///home/anandu_2004/manipulator_ws/install/cambot_description/share/cambot_description/meshes/left_strcamera_1.stl" scale="0.001 0.001 0.001"/>
      </geometry>
      <material name="red"/>
    </visual>
    <collision>
      <origin rpy="0 0 0" xyz="-0.585826 0.115 -0.340826"/>
      <geometry>
        <mesh filename="file:///home/anandu_2004/manipulator_ws/install/cambot_description/share/cambot_description/meshes/left_strcamera_1.stl" scale="0.001 0.001 0.001"/>
      </geometry>
    </collision>
  </link>
  <link name="right_strcamera_1">
    <inertial>
      <origin rpy="0 0 0" xyz="-0.5340002394741429 -0.013999998286366513 0.43022693608457757"/>
      <mass value="0.0002297800954592406"/>
      <inertia ixx="0.0" ixy="0.0" ixz="-0.0" iyy="0.0" iyz="-0.0" izz="0.0"/>
    </inertial>
    <visual>
      <origin rpy="0 0 0" xyz="-0.585826 0.115 -0.340826"/>
      <geometry>
        <mesh filename="file:///home/anandu_2004/manipulator_ws/install/cambot_description/share/cambot_description/meshes/right_strcamera_1.stl" scale="0.001 0.001 0.001"/>
      </geometry>
      <material name="red"/>
    </visual>
    <collision>
      <origin rpy="0 0 0" xyz="-0.585826 0.115 -0.340826"/>
      <geometry>
        <mesh filename="file:///home/anandu_2004/manipulator_ws/install/cambot_description/share/cambot_description/meshes/right_strcamera_1.stl" scale="0.001 0.001 0.001"/>
      </geometry>
    </collision>
  </link>
  <joint name="base_joint" type="continuous">
    <origin rpy="0 0 0" xyz="0.045826 -0.02 0.18"/>
    <parent link="base_link"/>
    <child link="shoulder_1"/>
    <axis xyz="0.0 0.0 1.0"/>
  </joint>
  <joint name="shoulder_joint" type="revolute">
    <origin rpy="0 0 0" xyz="0.0 -0.05 0.115"/>
    <parent link="shoulder_1"/>
    <child link="elbow_1"/>
    <axis xyz="-0.0 -1.0 0.0"/>
    <limit effort="100" lower="-1.570796" upper="1.570796" velocity="100"/>
  </joint>
  <joint name="elbow_joint" type="revolute">
    <origin rpy="0 0 0" xyz="0.0 -0.015 0.1"/>
    <parent link="elbow_1"/>
    <child link="proximal_wrist_1"/>
    <axis xyz="0.0 1.0 -0.0"/>
    <limit effort="100" lower="-0.872665" upper="0.872665" velocity="100"/>
  </joint>
  <joint name="proximal_wrist_joint" type="revolute">
    <origin rpy="0 0 0" xyz="0.0 0.015 0.085"/>
    <parent link="proximal_wrist_1"/>
    <child link="intermediate_wrist_1"/>
    <axis xyz="-0.0 -1.0 -0.0"/>
    <limit effort="100" lower="-1.047198" upper="1.047198" velocity="100"/>
  </joint>
  <joint name="inter_wrist_joint" type="revolute">
    <origin rpy="0 0 0" xyz="0.0 -0.015 0.1"/>
    <parent link="intermediate_wrist_1"/>
    <child link="distal_wrist_1"/>
    <axis xyz="0.0 1.0 0.0"/>
    <limit effort="100" lower="-1.570796" upper="1.570796" velocity="100"/>
  </joint>
  <joint name="distal_wrist_joint" type="revolute">
    <origin rpy="0 0 0" xyz="0.0 0.015 0.085"/>
    <parent link="distal_wrist_1"/>
    <child link="distal_section_1"/>
    <axis xyz="-0.0 -1.0 -0.0"/>
    <limit effort="100" lower="-1.570796" upper="1.570796" velocity="100"/>
  </joint>
  <joint name="tool_joint" type="continuous">
    <origin rpy="0 0 0" xyz="0.0 -0.055 0.08"/>
    <parent link="distal_section_1"/>
    <child link="tool_flange_1"/>
    <axis xyz="0.0 -0.0 1.0"/>
  </joint>
  <joint name="camera_joint" type="fixed">
    <origin rpy="0 0 0" xyz="0.0 0.0 0.025"/>
    <parent link="tool_flange_1"/>
    <child link="camera_1"/>
  </joint>
  <joint name="leftstrcamera_joint" type="fixed">
    <origin rpy="0 0 0" xyz="0.54 0.01 -0.404174"/>
    <parent link="tool_flange_1"/>
    <child link="left_strcamera_1"/>
  </joint>
  <joint name="rightstrcamera_joint" type="fixed">
    <origin rpy="0 0 0" xyz="0.54 0.01 -0.404174"/>
    <parent link="tool_flange_1"/>
    <child link="right_strcamera_1"/>
  </joint>
</robot>
